Workbook

Sheet Dashboard
A1: Branch & Recruiter Revenue Dashboard
A4: KPI | B4: Value | D4: Branch | E4: Payment Received | F4: Pending (PP + IP) | G4: Gross Billing
A5: Placements | B5: =SUM('Branch Summary'!C2:C6) -> 527 | D5: Bangalore | E5: ='Branch Summary'!E2 -> 9498397.6 | F5: ='Branch Summary'!F2+'Branch Summary'!G2 -> 8246981 | G5: ='Branch Summary'!D2 -> 17745379
A6: Recruiter Groups | B6: =SUM('Branch Summary'!B2:B6) -> 88 | D6: Delhi | E6: ='Branch Summary'!E3 -> 12563961 | F6: ='Branch Summary'!F3+'Branch Summary'!G3 -> 4928433.5 | G6: ='Branch Summary'!D3 -> 17693388
A7: Gross Billing | B7: =SUM('Branch Summary'!D2:D6) -> 53126755 | D7: Faridabad | E7: ='Branch Summary'!E4 -> 8042801.9 | F7: ='Branch Summary'!F4+'Branch Summary'!G4 -> 972160.88 | G7: ='Branch Summary'!D4 -> 9074938.8
A8: Payment Received | B8: =SUM('Branch Summary'!E2:E6) -> 35269288 | D8: Gurgaon | E8: ='Branch Summary'!E5 -> 4504175.7 | F8: ='Branch Summary'!F5+'Branch Summary'!G5 -> 3107706.7 | G8: ='Branch Summary'!D5 -> 7611882.4
A9: Pending (PP + IP) | B9: =SUM('Branch Summary'!F2:F6)+SUM('Branch Summary'!G2:G6) -> 17596498 | D9: Hyderabad | E9: ='Branch Summary'!E6 -> 659951.64 | F9: ='Branch Summary'!F6+'Branch Summary'!G6 -> 341216 | G9: ='Branch Summary'!D6 -> 1001167.6
A10: Active Revenue | B10: =SUM('Branch Summary'!K2:K6) -> 52865786
A11: Realization % | B11: =IFERROR(B8/B10,0) -> 0.66714771
A12: Records Needing Review | B12: =14 -> 14
A15: Report Notes
A16: Revenue uses Billing Amount. Branch variants Bengaluru/Banglaore are standardized to Bangalore. Blank recruiter records are retained under 'Unassigned / Blank Recruiter' so the placement total fully reconciles. Payment status 'pp' is standardized to PP. Blank Billing Amounts are excluded from revenue totals, and the invoice-like payment status value is retained as Other / Review. Original source values remain in Sorted Data.

Sheet Branch Summary
A1: Branch | B1: Recruiter Groups | C1: Placements | D1: Gross Billing | E1: Payment Received | F1: PP | G1: IP | H1: Backout | I1: Credit Note | J1: Other / Review | K1: Active Revenue | L1: Realization % | M1: Avg Revenue / Placement
A2: Gurgaon | B2: =COUNTIF('Recruiter Revenue'!$A:$A,$A2) -> 25 | C2: =SUMIF('Recruiter Revenue'!$A:$A,$A2,'Recruiter Revenue'!$D:$D) -> 166 | D2: =SUMIF('Recruiter Revenue'!$A:$A,$A2,'Recruiter Revenue'!$E:$E) -> 17745379 | E2: =SUMIF('Recruiter Revenue'!$A:$A,$A2,'Recruiter Revenue'!$F:$F) -> 9498397.6 | F2: =SUMIF('Recruiter Revenue'!$A:$A,$A2,'Recruiter Revenue'!$G:$G) -> 5245981 | G2: =SUMIF('Recruiter Revenue'!$A:$A,$A2,'Recruiter Revenue'!$H:$H) -> 3001000 | H2: =SUMIF('Recruiter Revenue'!$A:$A,$A2,'Recruiter Revenue'!$I:$I) -> 0 | I2: =SUMIF('Recruiter Revenue'!$A:$A,$A2,'Recruiter Revenue'!$J:$J) -> 0 | J2: =SUMIF('Recruiter Revenue'!$A:$A,$A2,'Recruiter Revenue'!$K:$K) -> 0 | K2: =SUMIF('Recruiter Revenue'!$A:$A,$A2,'Recruiter Revenue'!$L:$L) -> 17745379 | L2: =IFERROR(E2/K2,0) -> 0.53526035 | M2: =IFERROR(D2/C2,0) -> 106899.87
A3: Delhi | B3: =COUNTIF('Recruiter Revenue'!$A:$A,$A3) -> 16 | C3: =SUMIF('Recruiter Revenue'!$A:$A,$A3,'Recruiter Revenue'!$D:$D) -> 180 | D3: =SUMIF('Recruiter Revenue'!$A:$A,$A3,'Recruiter Revenue'!$E:$E) -> 17693388 | E3: =SUMIF('Recruiter Revenue'!$A:$A,$A3,'Recruiter Revenue'!$F:$F) -> 12563961 | F3: =SUMIF('Recruiter Revenue'!$A:$A,$A3,'Recruiter Revenue'!$G:$G) -> 3922470.7 | G3: =SUMIF('Recruiter Revenue'!$A:$A,$A3,'Recruiter Revenue'!$H:$H) -> 1005962.8 | H3: =SUMIF('Recruiter Revenue'!$A:$A,$A3,'Recruiter Revenue'!$I:$I) -> 0 | I3: =SUMIF('Recruiter Revenue'!$A:$A,$A3,'Recruiter Revenue'!$J:$J) -> 154899.5 | J3: =SUMIF('Recruiter Revenue'!$A:$A,$A3,'Recruiter Revenue'!$K:$K) -> 46094 | K3: =SUMIF('Recruiter Revenue'!$A:$A,$A3,'Recruiter Revenue'!$L:$L) -> 17492394 | L3: =IFERROR(E3/K3,0) -> 0.71825278 | M3: =IFERROR(D3/C3,0) -> 98296.599
A4: Faridabad | B4: =COUNTIF('Recruiter Revenue'!$A:$A,$A4) -> 23 | C4: =SUMIF('Recruiter Revenue'!$A:$A,$A4,'Recruiter Revenue'!$D:$D) -> 127 | D4: =SUMIF('Recruiter Revenue'!$A:$A,$A4,'Recruiter Revenue'!$E:$E) -> 9074938.8 | E4: =SUMIF('Recruiter Revenue'!$A:$A,$A4,'Recruiter Revenue'!$F:$F) -> 8042801.9 | F4: =SUMIF('Recruiter Revenue'!$A:$A,$A4,'Recruiter Revenue'!$G:$G) -> 794419.88 | G4: =SUMIF('Recruiter Revenue'!$A:$A,$A4,'Recruiter Revenue'!$H:$H) -> 177741 | H4: =SUMIF('Recruiter Revenue'!$A:$A,$A4,'Recruiter Revenue'!$I:$I) -> 0 | I4: =SUMIF('Recruiter Revenue'!$A:$A,$A4,'Recruiter Revenue'!$J:$J) -> 59976 | J4: =SUMIF('Recruiter Revenue'!$A:$A,$A4,'Recruiter Revenue'!$K:$K) -> 0 | K4: =SUMIF('Recruiter Revenue'!$A:$A,$A4,'Recruiter Revenue'!$L:$L) -> 9014962.8 | L4: =IFERROR(E4/K4,0) -> 0.89216141 | M4: =IFERROR(D4/C4,0) -> 71456.211
A5: Bangalore | B5: =COUNTIF('Recruiter Revenue'!$A:$A,$A5) -> 22 | C5: =SUMIF('Recruiter Revenue'!$A:$A,$A5,'Recruiter Revenue'!$D:$D) -> 47 | D5: =SUMIF('Recruiter Revenue'!$A:$A,$A5,'Recruiter Revenue'!$E:$E) -> 7611882.4 | E5: =SUMIF('Recruiter Revenue'!$A:$A,$A5,'Recruiter Revenue'!$F:$F) -> 4504175.7 | F5: =SUMIF('Recruiter Revenue'!$A:$A,$A5,'Recruiter Revenue'!$G:$G) -> 1931979.4 | G5: =SUMIF('Recruiter Revenue'!$A:$A,$A5,'Recruiter Revenue'!$H:$H) -> 1175727.2 | H5: =SUMIF('Recruiter Revenue'!$A:$A,$A5,'Recruiter Revenue'!$I:$I) -> 0 | I5: =SUMIF('Recruiter Revenue'!$A:$A,$A5,'Recruiter Revenue'!$J:$J) -> 0 | J5: =SUMIF('Recruiter Revenue'!$A:$A,$A5,'Recruiter Revenue'!$K:$K) -> 0 | K5: =SUMIF('Recruiter Revenue'!$A:$A,$A5,'Recruiter Revenue'!$L:$L) -> 7611882.4 | L5: =IFERROR(E5/K5,0) -> 0.59172955 | M5: =IFERROR(D5/C5,0) -> 161954.94
A6: Hyderabad | B6: =COUNTIF('Recruiter Revenue'!$A:$A,$A6) -> 2 | C6: =SUMIF('Recruiter Revenue'!$A:$A,$A6,'Recruiter Revenue'!$D:$D) -> 7 | D6: =SUMIF('Recruiter Revenue'!$A:$A,$A6,'Recruiter Revenue'!$E:$E) -> 1001167.6 | E6: =SUMIF('Recruiter Revenue'!$A:$A,$A6,'Recruiter Revenue'!$F:$F) -> 659951.64 | F6: =SUMIF('Recruiter Revenue'!$A:$A,$A6,'Recruiter Revenue'!$G:$G) -> 295401 | G6: =SUMIF('Recruiter Revenue'!$A:$A,$A6,'Recruiter Revenue'!$H:$H) -> 45815 | H6: =SUMIF('Recruiter Revenue'!$A:$A,$A6,'Recruiter Revenue'!$I:$I) -> 0 | I6: =SUMIF('Recruiter Revenue'!$A:$A,$A6,'Recruiter Revenue'!$J:$J) -> 0 | J6: =SUMIF('Recruiter Revenue'!$A:$A,$A6,'Recruiter Revenue'!$K:$K) -> 0 | K6: =SUMIF('Recruiter Revenue'!$A:$A,$A6,'Recruiter Revenue'!$L:$L) -> 1001167.6 | L6: =IFERROR(E6/K6,0) -> 0.65918195 | M6: =IFERROR(D6/C6,0) -> 143023.95
A7: TOTAL | B7: =SUM(B2:B6) -> 88 | C7: =SUM(C2:C6) -> 527 | D7: =SUM(D2:D6) -> 53126755 | E7: =SUM(E2:E6) -> 35269288 | F7: =SUM(F2:F6) -> 12190252 | G7: =SUM(G2:G6) -> 5406246 | H7: =SUM(H2:H6) -> 0 | I7: =SUM(I2:I6) -> 214875.5 | ... K7: =SUM(K2:K6) -> 52865786 | L7: =IFERROR(E7/K7,0) -> 0.66714771 | M7: =IFERROR(D7/C7,0) -> 100809.78

Sheet Recruiter Revenue
A1: Branch | B1: Account Manager | C1: Recruiter | D1: Placements | E1: Gross Billing | F1: Payment Received | G1: PP | H1: IP | I1: Backout | J1: Credit Note | K1: Other / Review | L1: Active Revenue | M1: Realization % | N1: Avg Revenue / Placement
A2: Delhi | B2: Manorma | C2: Prabhat Panchal | D2: =COUNTIFS('Sorted Data'!$C:$C,$A2,'Sorted Data'!$E:$E,$B2,'Sorted Data'!$G:$G,$C2) -> 36 | E2: =SUMIFS('Sorted Data'!$Q:$Q,'Sorted Data'!$C:$C,$A2,'Sorted Data'!$E:$E,$B2,'Sorted Data'!$G:$G,$C2) -> 3069553.2 | F2: =SUMIFS('Sorted Data'!$Q:$Q,'Sorted Data'!$C:$C,$A2,'Sorted Data'!$E:$E,$B2,'Sorted Data'!$G:$G,$C2,'Sorted Data'!$T:$T,"Payment Received") -> 2249970.8 | G2: =SUMIFS('Sorted Data'!$Q:$Q,'Sorted Data'!$C:$C,$A2,'Sorted Data'!$E:$E,$B2,'Sorted Data'!$G:$G,$C2,'Sorted Data'!$T:$T,"PP") -> 522902.4 | H2: =SUMIFS('Sorted Data'!$Q:$Q,'Sorted Data'!$C:$C,$A2,'Sorted Data'!$E:$E,$B2,'Sorted Data'!$G:$G,$C2,'Sorted Data'!$T:$T,"IP") -> 260000 | I2: =SUMIFS('Sorted Data'!$Q:$Q,'Sorted Data'!$C:$C,$A2,'Sorted Data'!$E:$E,$B2,'Sorted Data'!$G:$G,$C2,'Sorted Data'!$T:$T,"Backout") -> 0 | J2: =SUMIFS('Sorted Data'!$Q:$Q,'Sorted Data'!$C:$C,$A2,'Sorted Data'!$E:$E,$B2,'Sorted Data'!$G:$G,$C2,'Sorted Data'!$T:$T,"Credit Note") -> 36680 | K2: =SUMIFS('Sorted Data'!$Q:$Q,'Sorted Data'!$C:$C,$A2,'Sorted Data'!$E:$E,$B2,'Sorted Data'!$G:$G,$C2,'Sorted Data'!$T:$T,"Other / Review") -> 0 | L2: =F2+G2+H2 -> 3032873.2 | M2: =IFERROR(F2/L2,0) -> 0.74186115 | N2: =IFERROR(E2/D2,0) -> 85265.366
A3: Delhi | B3: Manorma | C3: Bhumika | D3: =COUNTIFS('Sorted Data'!$C:$C,$A3,'Sorted Data'!$E:$E,$B3,'Sorted Data'!$G:$G,$C3) -> 9 | E3: =SUMIFS('Sorted Data'!$Q:$Q,'Sorted Data'!$C:$C,$A3,'Sorted Data'!$E:$E,$B3,'Sorted Data'!$G:$G,$C3) -> 2722141 | F3: =SUMIFS('Sorted Data'!$Q:$Q,'Sorted Data'!$C:$C,$A3,'Sorted Data'!$E:$E,$B3,'Sorted Data'!$G:$G,$C3,'Sorted Data'!$T:$T,"Payment Received") -> 900140.96 | G3: =SUMIFS('Sorted Data'!$Q:$Q,'Sorted Data'!$C:$C,$A3,'Sorted Data'!$E:$E,$B3,'Sorted Data'!$G:$G,$C3,'Sorted Data'!$T:$T,"PP") -> 1422000 | H3: =SUMIFS('Sorted Data'!$Q:$Q,'Sorted Data'!$C:$C,$A3,'Sorted Data'!$E:$E,$B3,'Sorted Data'!$G:$G,$C3,'Sorted Data'!$T:$T,"IP") -> 400000 | I3: =SUMIFS('Sorted Data'!$Q:$Q,'Sorted Data'!$C:$C,$A3,'Sorted Data'!$E:$E,$B3,'Sorted Data'!$G:$G,$C3,'Sorted Data'!$T:$T,"Backout") -> 0 | J3: =SUMIFS('Sorted Data'!$Q:$Q,'Sorted Data'!$C:$C,$A3,'Sorted Data'!$E:$E,$B3,'Sorted Data'!$G:$G,$C3,'Sorted Data'!$T:$T,"Credit Note") -> 0 | K3: =SUMIFS('Sorted Data'!$Q:$Q,'Sorted Data'!$C:$C,$A3,'Sorted Data'!$E:$E,$B3,'Sorted Data'!$G:$G,$C3,'Sorted Data'!$T:$T,"Other / Review") -> 0 | L3: =F3+G3+H3 -> 2722141 | M3: =IFERROR(F3/L3,0) -> 0.3306739 | N3: =IFERROR(E3/D3,0) -> 302460.11
A4: Gurgaon | B4: Rohit Yadav | C4: Jatin | D4: =COUNTIFS('Sorted Data'!$C:$C,$A4,'Sorted Data'!$E:$E,$B4,'Sorted Data'!$G:$G,$C4) -> 12 | E4: =SUMIFS('Sorted Data'!$Q:$Q,'Sorted Data'!$C:$C,$A4,'Sorted Data'!$E:$E,$B4,'Sorted Data'!$G:$G,$C4) -> 2584816.7 | F4: =SUMIFS('Sorted Data'!$Q:$Q,'Sorted Data'!$C:$C,$A4,'Sorted Data'!$E:$E,$B4,'Sorted Data'!$G:$G,$C4,'Sorted Data'!$T:$T,"Payment Received") -> 1188266.8 | G4: =SUMIFS('Sorted Data'!$Q:$Q,'Sorted Data'!$C:$C,$A4,'Sorted Data'!$E:$E,$B4,'Sorted Data'!$G:$G,$C4,'Sorted Data'!$T:$T,"PP") -> 1396549.9 | H4: =SUMIFS('Sorted Data'!$Q:$Q,'Sorted Data'!$C:$C,$A4,'Sorted Data'!$E:$E,$B4,'Sorted Data'!$G:$G,$C4,'Sorted Data'!$T:$T,"IP") -> 0 | I4: =SUMIFS('Sorted Data'!$Q:$Q,'Sorted Data'!$C:$C,$A4,'Sorted Data'!$E:$E,$B4,'Sorted Data'!$G:$G,$C4,'Sorted Data'!$T:$T,"Backout") -> 0 | J4: =SUMIFS('Sorted Data'!$Q:$Q,'Sorted Data'!$C:$C,$A4,'Sorted Data'!$E:$E,$B4,'Sorted Data'!$G:$G,$C4,'Sorted Data'!$T:$T,"Credit Note") -> 0 | K4: =SUMIFS('Sorted Data'!$Q:$Q,'Sorted Data'!$C:$C,$A4,'Sorted Data'!$E:$E,$B4,'Sorted Data'!$G:$G,$C4,'Sorted Data'!$T:$T,"Other / Review") -> 0 | L4: =F4+G4+H4 -> 2584816.7 | M4: =IFERROR(F4/L4,0) -> 0.45971026 | N4: =IFERROR(E4/D4,0) -> 215401.39
A5: Gurgaon | B5: Rohit Yadav | C5: Ajit Yadav | D5: =COUNTIFS('Sorted Data'!$C:$C,$A5,'Sorted Data'!$E:$E,$B5,'Sorted Data'!$G:$G,$C5) -> 13 | E5: =SUMIFS('Sorted Data'!$Q:$Q,'Sorted Data'!$C:$C,$A5,'Sorted Data'!$E:$E,$B5,'Sorted Data'!$G:$G,$C5) -> 2469999.5 | F5: =SUMIFS('Sorted Data'!$Q:$Q,'Sorted Data'!$C:$C,$A5,'Sorted Data'!$E:$E,$B5,'Sorted Data'!$G:$G,$C5,'Sorted Data'!$T:$T,"Payment Received") -> 1243825.5 | G5: =SUMIFS('Sorted Data'!$Q:$Q,'Sorted Data'!$C:$C,$A5,'Sorted Data'!$E:$E,$B5,'Sorted Data'!$G:$G,$C5,'Sorted Data'!$T:$T,"PP") -> 1056174 | H5: =SUMIFS('Sorted Data'!$Q:$Q,'Sorted Data'!$C:$C,$A5,'Sorted Data'!$E:$E,$B5,'Sorted Data'!$G:$G,$C5,'Sorted Data'!$T:$T,"IP") -> 170000 | I5: =SUMIFS('Sorted Data'!$Q:$Q,'Sorted Data'!$C:$C,$A5,'Sorted Data'!$E:$E,$B5,'Sorted Data'!$G:$G,$C5,'Sorted Data'!$T:$T,"Backout") -> 0 | J5: =SUMIFS('Sorted Data'!$Q:$Q,'Sorted Data'!$C:$C,$A5,'Sorted Data'!$E:$E,$B5,'Sorted Data'!$G:$G,$C5,'Sorted Data'!$T:$T,"Credit Note") -> 0 | K5: =SUMIFS('Sorted Data'!$Q:$Q,'Sorted Data'!$C:$C,$A5,'Sorted Data'!$E:$E,$B5,'Sorted Data'!$G:$G,$C5,'Sorted Data'!$T:$T,"Other / Review") -> 0 | L5: =F5+G5+H5 -> 2469999.5 | M5: =IFERROR(F5/L5,0) -> 0.50357318 | N5: =IFERROR(E5/D5,0) -> 189999.96
A6: Delhi | B6: Manorma | C6: Yamini | D6: =COUNTIFS('Sorted Data'!$C:$C,$A6,'Sorted Data'!$E:$E,$B6,'Sorted Data'!$G:$G,$C6) -> 11 | E6: =SUMIFS('Sorted Data'!$Q:$Q,'Sorted Data'!$C:$C,$A6,'Sorted Data'!$E:$E,$B6,'Sorted Data'!$G:$G,$C6) -> 2163653.1 | F6: =SUMIFS('Sorted Data'!$Q:$Q,'Sorted Data'!$C:$C,$A6,'Sorted Data'!$E:$E,$B6,'Sorted Data'!$G:$G,$C6,'Sorted Data'!$T:$T,"Payment Received") -> 1560433.6 | G6: =SUMIFS('Sorted Data'!$Q:$Q,'Sorted Data'!$C:$C,$A6,'Sorted Data'!$E:$E,$B6,'Sorted Data'!$G:$G,$C6,'Sorted Data'!$T:$T,"PP") -> 527000 | H6: =SUMIFS('Sorted Data'!$Q:$Q,'Sorted Data'!$C:$C,$A6,'Sorted Data'!$E:$E,$B6,'Sorted Data'!$G:$G,$C6,'Sorted Data'!$T:$T,"IP") -> 0 | I6: =SUMIFS('Sorted Data'!$Q:$Q,'Sorted Data'!$C:$C,$A6,'Sorted Data'!$E:$E,$B6,'Sorted Data'!$G:$G,$C6,'Sorted Data'!$T:$T,"Backout") -> 0 | J6: =SUMIFS('Sorted Data'!$Q:$Q,'Sorted Data'!$C:$C,$A6,'Sorted Data'!$E:$E,$B6,'Sorted Data'!$G:$G,$C6,'Sorted Data'!$T:$T,"Credit Note") -> 76219.5 | K6: =SUMIFS('Sorted Data'!$Q:$Q,'Sorted Data'!$C:$C,$A6,'Sorted Data'!$E:$E,$B6,'Sorted Data'!$G:$G,$C6,'Sorted Data'!$T:$T,"Other / Review") -> 0 | L6: =F6+G6+H6 -> 2087433.6 | M6: =IFERROR(F6/L6,0) -> 0.74753688 | N6: =IFERROR(E6/D6,0) -> 196695.74
A7: Gurgaon | B7: Rohit Yadav | C7: Robin | D7: =COUNTIFS('Sorted Data'!$C:$C,$A7,'Sorted Data'!$E:$E,$B7,'Sorted Data'!$G:$G,$C7) -> 23 | E7: =SUMIFS('Sorted Data'!$Q:$Q,'Sorted Data'!$C:$C,$A7,'Sorted Data'!$E:$E,$B7,'Sorted Data'!$G:$G,$C7) -> 2095497.8 | F7: =SUMIFS('Sorted Data'!$Q:$Q,'Sorted Data'!$C:$C,$A7,'Sorted Data'!$E:$E,$B7,'Sorted Data'!$G:$G,$C7,'Sorted Data'!$T:$T,"Payment Received") -> 1655497.8 | G7: =SUMIFS('Sorted Data'!$Q:$Q,'Sorted Data'!$C:$C,$A7,'Sorted Data'!$E:$E,$B7,'Sorted Data'!$G:$G,$C7,'Sorted Data'!$T:$T,"PP") -> 0 | H7: =SUMIFS('Sorted Data'!$Q:$Q,'Sorted Data'!$C:$C,$A7,'Sorted Data'!$E:$E,$B7,'Sorted Data'!$G:$G,$C7,'Sorted Data'!$T:$T,"IP") -> 440000 | I7: =SUMIFS('Sorted Data'!$Q:$Q,'Sorted Data'!$C:$C,$A7,'Sorted Data'!$E:$E,$B7,'Sorted Data'!$G:$G,$C7,'Sorted Data'!$T:$T,"Backout") -> 0 | J7: =SUMIFS('Sorted Data'!$Q:$Q,'Sorted Data'!$C:$C,$A7,'Sorted Data'!$E:$E,$B7,'Sorted Data'!$G:$G,$C7,'Sorted Data'!$T:$T,"Credit Note") -> 0 | K7: =SUMIFS('Sorted Data'!$Q:$Q,'Sorted Data'!$C:$C,$A7,'Sorted Data'!$E:$E,$B7,'Sorted Data'!$G:$G,$C7,'Sorted Data'!$T:$T,"Other / Review") -> 0 | L7: =F7+G7+H7 -> 2095497.8 | M7: =IFERROR(F7/L7,0) -> 0.79002602 | N7: =IFERROR(E7/D7,0) -> 91108.598
A8: Gurgaon | B8: Rohit Yadav | C8: Priyanka | D8: =COUNTIFS('Sorted Data'!$C:$C,$A8,'Sorted Data'!$E:$E,$B8,'Sorted Data'!$G:$G,$C8) -> 24 | E8: =SUMIFS('Sorted Data'!$Q:$Q,'Sorted Data'!$C:$C,$A8,'Sorted Data'!$E:$E,$B8,'Sorted Data'!$G:$G,$C8) -> 1959613.6 | F8: =SUMIFS('Sorted Data'!$Q:$Q,'Sorted Data'!$C:$C,$A8,'Sorted Data'!$E:$E,$B8,'Sorted Data'!$G:$G,$C8,'Sorted Data'!$T:$T,"Payment Received") -> 666063.47 | G8: =SUMIFS('Sorted Data'!$Q:$Q,'Sorted Data'!$C:$C,$A8,'Sorted Data'!$E:$E,$B8,'Sorted Data'!$G:$G,$C8,'Sorted Data'!$T:$T,"PP") -> 511550.12 | H8: =SUMIFS('Sorted Data'!$Q:$Q,'Sorted Data'!$C:$C,$A8,'Sorted Data'!$E:$E,$B8,'Sorted Data'!$G:$G,$C8,'Sorted Data'!$T:$T,"IP") -> 782000 | I8: =SUMIFS('Sorted Data'!$Q:$Q,'Sorted Data'!$C:$C,$A8,'Sorted Data'!$E:$E,$B8,'Sorted Data'!$G:$G,$C8,'Sorted Data'!$T:$T,"Backout") -> 0 | J8: =SUMIFS('Sorted Data'!$Q:$Q,'Sorted Data'!$C:$C,$A8,'Sorted Data'!$E:$E,$B8,'Sorted Data'!$G:$G,$C8,'Sorted Data'!$T:$T,"Credit Note") -> 0 | K8: =SUMIFS('Sorted Data'!$Q:$Q,'Sorted Data'!$C:$C,$A8,'Sorted Data'!$E:$E,$B8,'Sorted Data'!$G:$G,$C8,'Sorted Data'!$T:$T,"Other / Review") -> 0 | L8: =F8+G8+H8 -> 1959613.6 | M8: =IFERROR(F8/L8,0) -> 0.33989531 | N8: =IFERROR(E8/D8,0) -> 81650.566
A9: Delhi | B9: Manorma | C9: Navya | D9: =COUNTIFS('Sorted Data'!$C:$C,$A9,'Sorted Data'!$E:$E,$B9,'Sorted Data'!$G:$G,$C9) -> 26 | E9: =SUMIFS('Sorted Data'!$Q:$Q,'Sorted Data'!$C:$C,$A9,'Sorted Data'!$E:$E,$B9,'Sorted Data'!$G:$G,$C9) -> 1845336.7 | F9: =SUMIFS('Sorted Data'!$Q:$Q,'Sorted Data'!$C:$C,$A9,'Sorted Data'!$E:$E,$B9,'Sorted Data'!$G:$G,$C9,'Sorted Data'!$T:$T,"Payment Received") -> 1455336.7 | G9: =SUMIFS('Sorted Data'!$Q:$Q,'Sorted Data'!$C:$C,$A9,'Sorted Data'!$E:$E,$B9,'Sorted Data'!$G:$G,$C9,'Sorted Data'!$T:$T,"PP") -> 348000 | H9: =SUMIFS('Sorted Data'!$Q:$Q,'Sorted Data'!$C:$C,$A9,'Sorted Data'!$E:$E,$B9,'Sorted Data'!$G:$G,$C9,'Sorted Data'!$T:$T,"IP") -> 0 | I9: =SUMIFS('Sorted Data'!$Q:$Q,'Sorted Data'!$C:$C,$A9,'Sorted Data'!$E:$E,$B9,'Sorted Data'!$G:$G,$C9,'Sorted Data'!$T:$T,"Backout") -> 0 | J9: =SUMIFS('Sorted Data'!$Q:$Q,'Sorted Data'!$C:$C,$A9,'Sorted Data'!$E:$E,$B9,'Sorted Data'!$G:$G,$C9,'Sorted Data'!$T:$T,"Credit Note") -> 42000 | K9: =SUMIFS('Sorted Data'!$Q:$Q,'Sorted Data'!$C:$C,$A9,'Sorted Data'!$E:$E,$B9,'Sorted Data'!$G:$G,$C9,'Sorted Data'!$T:$T,"Other / Review") -> 0 | L9: =F9+G9+H9 -> 1803336.7 | M9: =IFERROR(F9/L9,0) -> 0.80702439 | N9: =IFERROR(E9/D9,0) -> 70974.489
A10: Bangalore | B10: Jayadev | C10: Navya | D10: =COUNTIFS('Sorted Data'!$C:$C,$A10,'Sorted Data'!$E:$E,$B10,'Sorted Data'!$G:$G,$C10) -> 4 | E10: =SUMIFS('Sorted Data'!$Q:$Q,'Sorted Data'!$C:$C,$A10,'Sorted Data'!$E:$E,$B10,'Sorted Data'!$G:$G,$C10) -> 1690880 | F10: =SUMIFS('Sorted Data'!$Q:$Q,'Sorted Data'!$C:$C,$A10,'Sorted Data'!$E:$E,$B10,'Sorted Data'!$G:$G,$C10,'Sorted Data'!$T:$T,"Payment Received") -> 1024000 | G10: =SUMIFS('Sorted Data'!$Q:$Q,'Sorted Data'!$C:$C,$A10,'Sorted Data'!$E:$E,$B10,'Sorted Data'!$G:$G,$C10,'Sorted Data'!$T:$T,"PP") -> 666880 | H10: =SUMIFS('Sorted Data'!$Q:$Q,'Sorted Data'!$C:$C,$A10,'Sorted Data'!$E:$E,$B10,'Sorted Data'!$G:$G,$C10,'Sorted Data'!$T:$T,"IP") -> 0 | I10: =SUMIFS('Sorted Data'!$Q:$Q,'Sorted Data'!$C:$C,$A10,'Sorted Data'!$E:$E,$B10,'Sorted Data'!$G:$G,$C10,'Sorted Data'!$T:$T,"Backout") -> 0 | J10: =SUMIFS('Sorted Data'!$Q:$Q,'Sorted Data'!$C:$C,$A10,'Sorted Data'!$E:$E,$B10,'Sorted Data'!$G:$G,$C10,'Sorted Data'!$T:$T,"Credit Note") -> 0 | K10: =SUMIFS('Sorted Data'!$Q:$Q,'Sorted Data'!$C:$C,$A10,'Sorted Data'!$E:$E,$B10,'Sorted Data'!$G:$G,$C10,'Sorted Data'!$T:$T,"Other / Review") -> 0 | L10: =F10+G10+H10 -> 1690880 | M10: =IFERROR(F10/L10,0) -> 0.60560182 | N10: =IFERROR(E10/D10,0) -> 422720
A11: Delhi | B11: Manorma | C11: Stuti | D11: =COUNTIFS('Sorted Data'!$C:$C,$A11,'Sorted Data'!$E:$E,$B11,'Sorted Data'!$G:$G,$C11) -> 14 | E11: =SUMIFS('Sorted Data'!$Q:$Q,'Sorted Data'!$C:$C,$A11,'Sorted Data'!$E:$E,$B11,'Sorted Data'!$G:$G,$C11) -> 1541860.8 | F11: =SUMIFS('Sorted Data'!$Q:$Q,'Sorted Data'!$C:$C,$A11,'Sorted Data'!$E:$E,$B11,'Sorted Data'!$G:$G,$C11,'Sorted Data'!$T:$T,"Payment Received") -> 1390813.5 | G11: =SUMIFS('Sorted Data'!$Q:$Q,'Sorted Data'!$C:$C,$A11,'Sorted Data'!$E:$E,$B11,'Sorted Data'!$G:$G,$C11,'Sorted Data'!$T:$T,"PP") -> 104953.33 | H11: =SUMIFS('Sorted Data'!$Q:$Q,'Sorted Data'!$C:$C,$A11,'Sorted Data'!$E:$E,$B11,'Sorted Data'!$G:$G,$C11,'Sorted Data'!$T:$T,"IP") -> 0 | I11: =SUMIFS('Sorted Data'!$Q:$Q,'Sorted Data'!$C:$C,$A11,'Sorted Data'!$E:$E,$B11,'Sorted Data'!$G:$G,$C11,'Sorted Data'!$T:$T,"Backout") -> 0 | J11: =SUMIFS('Sorted Data'!$Q:$Q,'Sorted Data'!$C:$C,$A11,'Sorted Data'!$E:$E,$B11,'Sorted Data'!$G:$G,$C11,'Sorted Data'!$T:$T,"Credit Note") -> 0 | K11: =SUMIFS('Sorted Data'!$Q:$Q,'Sorted Data'!$C:$C,$A11,'Sorted Data'!$E:$E,$B11,'Sorted Data'!$G:$G,$C11,'Sorted Data'!$T:$T,"Other / Review") -> 46094 | L11: =F11+G11+H11 -> 1495766.8 | M11: =IFERROR(F11/L11,0) -> 0.92983309 | N11: =IFERROR(E11/D11,0) -> 110132.92
A12: Delhi | B12: Manorma | C12: Kavita | D12: =COUNTIFS('Sorted Data'!$C:$C,$A12,'Sorted Data'!$E:$E,$B12,'Sorted Data'!$G:$G,$C12) -> 17 | E12: =SUMIFS('Sorted Data'!$Q:$Q,'Sorted Data'!$C:$C,$A12,'Sorted Data'!$E:$E,$B12,'Sorted Data'!$G:$G,$C12) -> 1392750.5 | F12: =SUMIFS('Sorted Data'!$Q:$Q,'Sorted Data'!$C:$C,$A12,'Sorted Data'!$E:$E,$B12,'Sorted Data'!$G:$G,$C12,'Sorted Data'!$T:$T,"Payment Received") -> 1200624.5 | G12: =SUMIFS('Sorted Data'!$Q:$Q,'Sorted Data'!$C:$C,$A12,'Sorted Data'!$E:$E,$B12,'Sorted Data'!$G:$G,$C12,'Sorted Data'!$T:$T,"PP") -> 120125.93 | H12: =SUMIFS('Sorted Data'!$Q:$Q,'Sorted Data'!$C:$C,$A12,'Sorted Data'!$E:$E,$B12,'Sorted Data'!$G:$G,$C12,'Sorted Data'!$T:$T,"IP") -> 72000 | I12: =SUMIFS('Sorted Data'!$Q:$Q,'Sorted Data'!$C:$C,$A12,'Sorted Data'!$E:$E,$B12,'Sorted Data'!$G:$G,$C12,'Sorted Data'!$T:$T,"Backout") -> 0 | J12: =SUMIFS('Sorted Data'!$Q:$Q,'Sorted Data'!$C:$C,$A12,'Sorted Data'!$E:$E,$B12,'Sorted Data'!$G:$G,$C12,'Sorted Data'!$T:$T,"Credit Note") -> 0 | K12: =SUMIFS('Sorted Data'!$Q:$Q,'Sorted Data'!$C:$C,$A12,'Sorted Data'!$E:$E,$B12,'Sorted Data'!$G:$G,$C12,'Sorted Data'!$T:$T,"Other / Review") -> 0 | L12: =F12+G12+H12 -> 1392750.5 | M12: =IFERROR(F12/L12,0) -> 0.86205287 | N12: =IFERROR(E12/D12,0) -> 81926.498
A13: Bangalore | B13: Avinash | C13: Rakshita | D13: =COUNTIFS('Sorted Data'!$C:$C,$A13,'Sorted Data'!$E:$E,$B13,'Sorted Data'!$G:$G,$C13) -> 7 | E13: =SUMIFS('Sorted Data'!$Q:$Q,'Sorted Data'!$C:$C,$A13,'Sorted Data'!$E:$E,$B13,'Sorted Data'!$G:$G,$C13) -> 1368610.1 | F13: =SUMIFS('Sorted Data'!$Q:$Q,'Sorted Data'!$C:$C,$A13,'Sorted Data'!$E:$E,$B13,'Sorted Data'!$G:$G,$C13,'Sorted Data'!$T:$T,"Payment Received") -> 1029418.8 | G13: =SUMIFS('Sorted Data'!$Q:$Q,'Sorted Data'!$C:$C,$A13,'Sorted Data'!$E:$E,$B13,'Sorted Data'!$G:$G,$C13,'Sorted Data'!$T:$T,"PP") -> 33320 | H13: =SUMIFS('Sorted Data'!$Q:$Q,'Sorted Data'!$C:$C,$A13,'Sorted Data'!$E:$E,$B13,'Sorted Data'!$G:$G,$C13,'Sorted Data'!$T:$T,"IP") -> 305871.34 | I13: =SUMIFS('Sorted Data'!$Q:$Q,'Sorted Data'!$C:$C,$A13,'Sorted Data'!$E:$E,$B13,'Sorted Data'!$G:$G,$C13,'Sorted Data'!$T:$T,"Backout") -> 0 | J13: =SUMIFS('Sorted Data'!$Q:$Q,'Sorted Data'!$C:$C,$A13,'Sorted Data'!$E:$E,$B13,'Sorted Data'!$G:$G,$C13,'Sorted Data'!$T:$T,"Credit Note") -> 0 | K13: =SUMIFS('Sorted Data'!$Q:$Q,'Sorted Data'!$C:$C,$A13,'Sorted Data'!$E:$E,$B13,'Sorted Data'!$G:$G,$C13,'Sorted Data'!$T:$T,"Other / Review") -> 0 | L13: =F13+G13+H13 -> 1368610.1 | M13: =IFERROR(F13/L13,0) -> 0.75216365 | N13: =IFERROR(E13/D13,0) -> 195515.73
... A89: Gurgaon | B89: Rohit Yadav | C89: Priyanaka | D89: =COUNTIFS('Sorted Data'!$C:$C,$A89,'Sorted Data'!$E:$E,$B89,'Sorted Data'!$G:$G,$C89) -> 1 | E89: =SUMIFS('Sorted Data'!$Q:$Q,'Sorted Data'!$C:$C,$A89,'Sorted Data'!$E:$E,$B89,'Sorted Data'!$G:$G,$C89) -> 0 | F89: =SUMIFS('Sorted Data'!$Q:$Q,'Sorted Data'!$C:$C,$A89,'Sorted Data'!$E:$E,$B89,'Sorted Data'!$G:$G,$C89,'Sorted Data'!$T:$T,"Payment Received") -> 0 | G89: =SUMIFS('Sorted Data'!$Q:$Q,'Sorted Data'!$C:$C,$A89,'Sorted Data'!$E:$E,$B89,'Sorted Data'!$G:$G,$C89,'Sorted Data'!$T:$T,"PP") -> 0 | H89: =SUMIFS('Sorted Data'!$Q:$Q,'Sorted Data'!$C:$C,$A89,'Sorted Data'!$E:$E,$B89,'Sorted Data'!$G:$G,$C89,'Sorted Data'!$T:$T,"IP") -> 0 | I89: =SUMIFS('Sorted Data'!$Q:$Q,'Sorted Data'!$C:$C,$A89,'Sorted Data'!$E:$E,$B89,'Sorted Data'!$G:$G,$C89,'Sorted Data'!$T:$T,"Backout") -> 0 | J89: =SUMIFS('Sorted Data'!$Q:$Q,'Sorted Data'!$C:$C,$A89,'Sorted Data'!$E:$E,$B89,'Sorted Data'!$G:$G,$C89,'Sorted Data'!$T:$T,"Credit Note") -> 0 | K89: =SUMIFS('Sorted Data'!$Q:$Q,'Sorted Data'!$C:$C,$A89,'Sorted Data'!$E:$E,$B89,'Sorted Data'!$G:$G,$C89,'Sorted Data'!$T:$T,"Other / Review") -> 0 | L89: =F89+G89+H89 -> 0 | M89: =IFERROR(F89/L89,0) -> 0 | N89: =IFERROR(E89/D89,0) -> 0

Sheet Sorted Data
A1: S.No | B1: Branch (Original) | C1: Branch (Standard) | D1: Account Manager (Original) | E1: Account Manager (Standard) | F1: Recruiter (Original) | G1: Recruiter (Standard) | H1: Organization | I1: Candidate Name | J1: Designation | K1: Department | L1: Location | M1: DOJ | N1: Offered CTC | O1: Invoice No. | P1: Billing Amount (Original) | Q1: Revenue (Numeric) | R1: Invoice Date | S1: Payment Status (Original) | T1: Payment Status (Standard) | U1: Data Quality Note
A2: 3538 | B2: Banglaore | C2: Bangalore | D2: Avinash | E2: Avinash | F2: Ajit / Avinash | G2: Ajit / Avinash | H2: Royal Enfield | I2: Priyadarshan | J2: Paint R&D | L2: Chennai | M2: 09.09.26 | N2: 1120000 | O2: Joined | P2: 23324 | Q2: 23324 | S2: IP | T2: IP | U2: Branch normalized: Banglaore → Bangalore
A3: 3420 | B3: Bengaluru | C3: Bangalore | D3: Avinash | E3: Avinash | F3: Jayadev | G3: Jayadev | H3: Mahindra AI | I3: Shivam S | J3: Sr. Data Science | L3: Bengaluru | M3: 16.07.26 | N3: 31,45,006 | O3: VHCPL/26-27/46 | P3: 3,14,500.60 | Q3: 314500.6 | R3: 30.7.2026 | S3: PP | T3: PP | U3: Branch normalized: Bengaluru → Bangalore
A4: 3012 | B4: Bangalore | C4: Bangalore | D4: Avinash | E4: Avinash | F4: Jayadev | G4: Jayadev | H4: Miebach | I4: Tejeshwar | J4: PM | L4: Mumbai | M4: 05.1.26 | N4: 4402000 | O4: VHCPL/25-26/102 | P4: 528240 | Q4: 528240 | R4: 13.02.2026 | S4: Payment Received | T4: Payment Received
A5: 3518 | B5: Bangalore | C5: Bangalore | D5: Avinash | E5: Avinash | F5: Lalitha Sri | G5: Lalitha Sri | H5: Royal Enfield | I5: Ahamed Basha | J5: Store & Warehouse | L5: Chennai | M5: 07.09.26 | N5: 4,00,000 | O5: PI/26-27/80 | P5: 33320 | Q5: 33320 | R5: 16.9.2026 | S5: IP | T5: IP
A6: 3517 | B6: Bangalore | C6: Bangalore | D6: Avinash | E6: Avinash | F6: Lalitha Sri | G6: Lalitha Sri | H6: Royal Enfield | I6: Parthiban P | J6: Store & Warehouse | L6: Chennai | M6: 07.09.26 | N6: 4,50,000 | O6: PI/26-27/80 | P6: 37485 | Q6: 37485 | R6: 16.9.2026 | S6: IP | T6: IP
A7: 3024 | B7: Bangalore | C7: Bangalore | D7: Avinash | E7: Avinash | F7: Navya | G7: Navya | H7: Best Auto | I7: Abhishek Jain | J7: Design Engineer | L7: Bilaspur | M7: 16.01.26 | N7: 516000 | O7: VHCPL/25-26/99 | P7: 42982.8 | Q7: 42982.8 | R7: 07.02.2026 | S7: Payment Received | T7: Payment Received
A8: 3519 | B8: Bengaluru | C8: Bangalore | D8: Avinash | E8: Avinash | F8: Navya | G8: Navya | H8: BFW | I8: Amol Pawar | J8: HR Business Partner (HR BP) - Sales, Marketing & Post-Sales | L8: Pune | M8: 07.09.26 | N8: 1400000 | O8: Joined | P8: 116620 | Q8: 116620 | S8: IP | T8: IP | U8: Branch normalized: Bengaluru → Bangalore
A9: 3421 | B9: Bengaluru | C9: Bangalore | D9: Avinash | E9: Avinash | F9: Navya | G9: Navya | H9: Royal Enfield | I9: Muralidharan G | J9: SE - MSE - Fabrication | L9: Chennai | M9: 20.07.26 | N9: 750000 | O9: VHCPL/26-27/81 | P9: 62475 | Q9: 62475 | R9: 17.9.2026 | S9: PP | T9: PP | U9: Branch normalized: Bengaluru → Bangalore
A10: 3462 | B10: Bangalore | C10: Bangalore | D10: Avinash | E10: Avinash | F10: Navya | G10: Navya | H10: Royal Enfield | I10: Vignesh.S | J10: Liquid Painting | L10: Chennai | M10: 17.08.26 | N10: 16,01,786 | O10: PI/26-27/79 | P10: 1,33,428.77 | Q10: 133428.77 | R10: 16.9.2026 | S10: IP | T10: IP
A11: 3205 | B11: Bangalore | C11: Bangalore | D11: Avinash | E11: Avinash | F11: Rakshita | G11: Rakshita | H11: Carraro | I11: Suyog Mashelkar | J11: Quality Head | L11: Pune | M11: 13.04.26 | N11: 4500000 | O11: VHC/26-27/31 | P11: 470285 | Q11: 470285 | R11: 13.5-2026 | S11: Payment Received | T11: Payment Received
A12: 3207 | B12: Bangalore | C12: Bangalore | D12: Avinash | E12: Avinash | F12: Rakshita | G12: Rakshita | H12: Miebach | I12: Saurav Kumar | J12: Sr. Consultant | L12: Gurgaon | M12: 13.04.26 | N12: 2900000 | O12: VHCPL/26-27/13 | P12: 290000 | Q12: 290000 | R12: 15.05.26 | S12: Payment Received | T12: Payment Received
A13: 3430 | B13: Banglaore | C13: Bangalore | D13: Avinash | E13: Avinash | F13: Rakshita | G13: Rakshita | H13: RE | I13: Thamilarasu | J13: Manufacturing Quality FTE | L13: Chennai | M13: 20.07.26 | N13: 400000 | O13: VHCPL/26-27/81 | P13: 33320 | Q13: 33320 | R13: 17.9.2026 | S13: PP | T13: PP | U13: Branch normalized: Banglaore → Bangalore
A14: 3502 | B14: Bengaluru | C14: Bangalore | D14: Avinash | E14: Avinash | F14: Rakshita | G14: Rakshita | H14: Royal Enfield | I14: Ganesh Ram | J14: Project & ME-Vehicle Assembly | L14: Chennai | M14: 31.08.26 | N14: 14,48,661 | O14: PI/26-27/79 | P14: 1,20,673.46 | Q14: 120673.46 | R14: 16.9.2026 | S14: IP | T14: IP | U14: Branch normalized: Bengaluru → Bangalore
A15: 3501 | B15: Bengaluru | C15: Bangalore | D15: Avinash | E15: Avinash | F15: Rakshita | G15: Rakshita | H15: Royal Enfield | I15: Indhuru D | J15: Project & ME-Machining | L15: Chennai | M15: 31.08.26 | N15: 6,16,121 | O15: PI/26-27/79 | P15: 51322.87 | Q15: 51322.87 | R15: 16.9.2026 | S15: IP | T15: IP | U15: Branch normalized: Bengaluru → Bangalore
A16: 3484 | B16: Banglaore | C16: Bangalore | D16: Avinash | E16: Avinash | F16: Rakshita | G16: Rakshita | H16: Royal Enfield | I16: Lakshmana Perumal.K | J16: Paint R&D | L16: Chennai | M16: 24.08.26 | N16: 16,07,143 | O16: PI/26-27/78 | P16: 1,33,875.01 | Q16: 133875.01 | R16: 16.9.2026 | S16: IP | T16: IP | U16: Branch normalized: Banglaore → Bangalore
A17: 3090 | B17: Bangalore | C17: Bangalore | D17: Avinash | E17: Avinash | F17: Rakshita | G17: Rakshita | H17: Shanthi Gear | I17: Senthil Murgun | J17: Head Finance | L17: Coimbatore | M17: 02.3.26 | N17: 3230898 | O17: VHCPL/25-26/107 | P17: 269133.8 | Q17: 269133.8 | R17: 05.03.2026 | S17: Payment Received | T17: Payment Received
A18: 3349 | B18: Bengaluru | C18: Bangalore | D18: Avinash | E18: Avinash | F18: shwetha | G18: Shwetha | H18: Mahindra AI | I18: Bhooyas Kapadia | J18: AI Engineer | L18: Mumbai | M18: 15.06.26 | N18: 2250000 | O18: VHCPL/26-27/36 | P18: 187425 | Q18: 187425 | R18: 8.7.2026 | S18: Payment Received | T18: Payment Received | U18: Branch normalized: Bengaluru → Bangalore; Recruiter normalized: shwetha → Shwetha
A19: 3434 | B19: Banglaore | C19: Bangalore | D19: Avinash | E19: Avinash | F19: Shwetha | G19: Shwetha | H19: RE | I19: Navya Satyanarayana. Gara | J19: FTE-ME-Machining | L19: Chennai | M19: 27.07.26 | N19: 350000 | O19: VHCPL/26-27/81 | P19: 35000 | Q19: 35000 | R19: 17.9.2026 | S19: PP | T19: PP | U19: Branch normalized: Banglaore → Bangalore
A20: 3485 | B20: Bengaluru | C20: Bangalore | D20: Avinash | E20: Avinash | F20: Shwetha | G20: Shwetha | H20: Royal Enfield | I20: Channabasava Hiremath | J20: Project & ME-Vehicle Assembly | L20: Chennai | M20: 24.08.26 | N20: 15,67,857 | O20: PI/26-27/78 | P20: 1,30,602.48 | Q20: 130602.48 | R20: 16.9.2026 | S20: IP | T20: IP | U20: Branch normalized: Bengaluru → Bangalore
A21: 3486 | B21: Banglaore | C21: Bangalore | D21: Avinash | E21: Avinash | F21: Shwetha | G21: Shwetha | H21: Royal Enfield | I21: Sanjay.S | J21: FTE-Product Enigneer | L21: Chennai | M21: 24.08.26 | N21: 4,50,000 | O21: PI/26-27/78 | P21: 37485 | Q21: 37485 | R21: 16.9.2026 | S21: IP | T21: IP | U21: Branch normalized: Banglaore → Bangalore
A22: 3537 | B22: Banglaore | C22: Bangalore | D22: Avinash | E22: Avinash | F22: Shwetha | G22: Shwetha | H22: Royal Enfield | I22: Santhoes kumar S | J22: Robotic Painting | L22: Chennai | M22: 07.09.26 | N22: 9,84,375 | O22: PI/26-27/80 | P22: 81998.43 | Q22: 81998.43 | R22: 16.9.2026 | S22: IP | T22: IP | U22: Branch normalized: Banglaore → Bangalore
A23: 3432 | B23: Bengaluru | C23: Bangalore | D23: Avinash | E23: Avinash | F23: Vedha | G23: Vedha | H23: RE | I23: Kushi Batta | J23: FTE Project & ME-Engine Assembly | L23: Chennai | M23: 27.07.26 | N23: 350000 | O23: VHCPL/26-27/81 | P23: 35000 | Q23: 35000 | R23: 17.9.2026 | S23: PP | T23: PP | U23: Branch normalized: Bengaluru → Bangalore
A24: 3487 | B24: Bengaluru | C24: Bangalore | D24: Avinash | E24: Avinash | F24: Vedha | G24: Vedha | H24: Royal Enfield | I24: Annamalai | J24: AM - SQA Sheet Metal | L24: Chennai | M24: 24.08.26 | N24: 7,18,214 | O24: PI/26-27/78 | P24: 59827.22 | Q24: 59827.22 | R24: 16.9.2026 | S24: IP | T24: IP | U24: Branch normalized: Bengaluru → Bangalore
A25: 3516 | B25: Banglaore | C25: Bangalore | D25: Avinash | E25: Avinash | F25: Vedha | G25: Vedha | H25: Royal Enfield | I25: Aravind E | J25: Maufacturing Quality | L25: Chennai | M25: 07.09.26 | N25: 4,50,000 | O25: PI/26-27/80 | P25: 37485 | Q25: 37485 | R25: 16.9.2026 | S25: IP | T25: IP | U25: Branch normalized: Banglaore → Bangalore
A26: 3450 | B26: Bangalore | C26: Bangalore | D26: Avinash | E26: Avinash | F26: Vedha | G26: Vedha | H26: Royal Enfield | I26: S. Dharani Kumar | J26: Paint | L26: Chennai | M26: 10.08.26 | N26: 12,50,000 | O26: PI/26-27/79 | P26: 1,04,125 | Q26: 104125 | R26: 16.9.2026 | S26: IP | T26: IP
A27: 3435 | B27: Bangalore | C27: Bangalore | D27: Avinash | E27: Avinash | F27: Visali | G27: Visali | H27: Miebach | I27: Twinkle | J27: HR | L27: Gurgaon | M27: 03.08.26 | N27: 1363000 | O27: VHCPL/26-27/68 | P27: 136300 | Q27: 136300 | R27: 3.9.2026 | S27: PP | T27: PP
A28: 3504 | B28: Bangalore | C28: Bangalore | D28: Avinash | E28: Avinash | F28: Visali | G28: Visali | H28: Royal Enfield | I28: Aravindsamy | J28: Store & Warehouse | L28: Chennai | M28: 31.08.26 | N28: 3,50,000 | O28: PI/26-27/80 | P28: 29155 | Q28: 29155 | R28: 16.9.2026 | S28: IP | T28: IP
A29: 3483 | B29: Bangalore | C29: Bangalore | D29: Avinash | E29: Avinash | F29: Visali | G29: Visali | H29: Royal Enfield | I29: Preethi S | J29: Store & Warehouse | L29: Chennai | M29: 24.08.26 | N29: 4,50,000 | O29: PI/26-27/80 | P29: 45000 | Q29: 45000 | R29: 16.9.2026 | S29: IP | T29: IP
A30: 3206 | B30: Bangalore | C30: Bangalore | D30: Haritha | E30: Haritha | F30: Shwetha | G30: Shwetha | H30: Miebach | I30: Nisha G Jammanakatti | J30: Hr & Admin | L30: Bangalore | M30: 13.04.26 | N30: 443000 | O30: VHCPL/26-27/13 | P30: 44300 | Q30: 44300 | R30: 15.05.26 | S30: Payment Received | T30: Payment Received
A31: 3375 | B31: Bengaluru | C31: Bangalore | D31: Jayadev | E31: Jayadev | F31: Jayadev | G31: Jayadev | H31: Borgwarner | I31: Sreeram PKJ | J31: Hardware Test Lead | L31: Bengaluru | M31: 06.07.26 | N31: 38,00,004 | O31: VHCPL/26-27/45 | P31: 3,73,517.59 | Q31: 373517.59 | R31: 22.7.2026 | S31: Payment Received | T31: Payment Received | U31: Branch normalized: Bengaluru → Bangalore
A32: 3463 | B32: Bengaluru | C32: Bangalore | D32: Jayadev | E32: Jayadev | F32: Navya | G32: Navya | H32: JSW | I32: Ajay Giri | J32: Solution /Data Architect | L32: Mumbai | M32: 17.08.26 | N32: 4380000 | O32: VHCPL/26-27/59 | P32: 438000 | Q32: 438000 | R32: 19.8.2026 | S32: PP | T32: PP | U32: Branch normalized: Bengaluru → Bangalore
A33: 3431 | B33: Bengaluru | C33: Bangalore | D33: Jayadev | E33: Jayadev | F33: Navya | G33: Navya | H33: JSW | I33: Ashish Bhavsar | J33: Product Management - Digitalization | L33: Mumbai | M33: 27.07.26 | N33: 28,61,000 | O33: VHCPL/26-27/49 | P33: 2,28,880 | Q33: 228880 | R33: 4.8.2026 | S33: PP | T33: PP | U33: Branch normalized: Bengaluru → Bangalore
A34: 3304 | B34: Bangalore | C34: Bangalore | D34: Jayadev | E34: Jayadev | F34: Navya | G34: Navya | H34: JSW | I34: Rupesh Kamble | J34: QA Engineer | L34: Mumbai | M34: 25.05.2026 | N34: 1550000 | O34: VHCPL/26-27/23 | P34: 124000 | Q34: 124000 | R34: 2.6.2026 | S34: Payment Received | T34: Payment Received
A35: 3091 | B35: Bangalore | C35: Bangalore | D35: Jayadev | E35: Jayadev | F35: Navya | G35: Navya | H35: JSW Energy | I35: Syed Iqbal | J35: Lead Data Scientist | L35: Mumbai | M35: 02.03.26 | N35: 7500000 | O35: VHCPL/25-26/111 | P35: 900000 | Q35: 900000 | R35: 10.03.2026 | S35: Payment Received | T35: Payment Received
A36: 3208 | B36: Bangalore | C36: Bangalore | D36: Jayadev | E36: Jayadev | F36: Rakshita | G36: Rakshita | H36: JSW Energy | I36: Souvik Ghosh | J36: DGM - Digital Lead | L36: Mumbai | M36: 20.04.26 | N36: 5900000 | O36: VHCPL/26-27/06 | P36: 590000 | Q36: 590000 | R36: 22.04.2026 | S36: Payment Received | T36: Payment Received
A37: 3303 | B37: Bangalore | C37: Bangalore | D37: Jayadev | E37: Jayadev | F37: Shwetha | G37: Shwetha | H37: Borgwarner | I37: Arnold Matthew | J37: ALM Tool Engineer | L37: Bangalore | M37: 07.05.26 | N37: 1100000 | O37: VHCPL/26-27/17 | P37: 87465 | Q37: 87465 | R37: 28.5.2026 | S37: Payment Received | T37: Payment Received
A38: 3515 | B38: Bangalore | C38: Bangalore | D38: Jayadev | E38: Jayadev | F38: Shwetha | G38: Shwetha | H38: Borgwarner | I38: Sanjay Gowda | J38: SIL Software Development Lead Engineer | L38: Bangalore | M38: 03.09.26 | N38: 2200000 | O38: VHCPL/26-27/70 | P38: 183260 | Q38: 183260 | R38: 8.9.2026 | S38: PP | T38: PP
A39: 3302 | B39: Bangalore | C39: Bangalore | D39: Navya | E39: Navya | F39: Avinash | G39: Avinash | H39: SAR Group | I39: Manjunath MP | J39: Manager BD | L39: Bangalore | M39: 04.05.26 | N39: 2846496 | O39: VHCPL/26-27/15 | P39: 237113.12 | Q39: 237113.12 | R39: 27.05.2026 | S39: Payment Received | T39: Payment Received
A40: 3308 | B40: Bangalore | C40: Bangalore | D40: Navya | E40: Navya | F40: Shwetha | G40: Shwetha | H40: SAR | I40: Nikitha SM | J40: Embedded Fimware Engineer | L40: Bangalore | M40: 08.06.26 | N40: 1048000 | O40: VHCPL/26-27/27 | P40: 87298.4 | Q40: 87298.4 | R40: 12.6.2026 | S40: Payment Received | T40: Payment Received
...

Sheet Data Quality
A1: Source Row | B1: S.No | C1: Branch | D1: Account Manager | E1: Recruiter | F1: Organization | G1: Candidate | H1: Billing Amount | I1: Payment Status | J1: Review Note | L1: Standardization / Review Item | M1: Count
A2: 26 | B2: 3312 | C2: Faridabad | D2: Bikash Das | E2: Madhuri | F2: JK Tilemaxx | G2: Shubam Gupta | I2: Backout | J2: Billing Amount blank | L2: Rows retained (S.No present) | M2: 527
A3: 42 | B3: 3167 | C3: Delhi | D3: Manorma | E3: Unassigned / Blank Recruiter | F3: Defsys | G3: Ajay Kumar Biswas | H3: 37485 | I3: Payment Received | J3: Recruiter blank; grouped as Unassigned / Blank Recruiter | L3: Trailing total-only rows excluded | M3: 2
A4: 128 | B4: 3026 | C4: Delhi | D4: Manorma | E4: Unassigned / Blank Recruiter | F4: Panasonic Corporate | G4: Malakkaran Aneesh Appukuttan | H4: 107623.6 | I4: Payment Received | J4: Recruiter blank; grouped as Unassigned / Blank Recruiter | L4: Bengaluru → Bangalore | M4: 13
A5: 173 | B5: 3395 | C5: Delhi | D5: Manorma | E5: Unassigned / Blank Recruiter | F5: JSW Energy | G5: Khushhal Agarwal | H5: 1,52,000 | I5: PP | J5: Recruiter blank; grouped as Unassigned / Blank Recruiter | L5: Banglaore → Bangalore | M5: 8
A6: 175 | B6: 3325 | C6: Delhi | D6: Manorma | E6: Unassigned / Blank Recruiter | F6: JKYMS | G6: Harpreet Singh | H6: 1,15,220.28 | I6: Payment Received | J6: Recruiter blank; grouped as Unassigned / Blank Recruiter | L6: Lowercase PP → PP | M6: 1
A7: 176 | B7: 3326 | C7: Delhi | D7: Manorma | E7: Unassigned / Blank Recruiter | F7: JKYMS | G7: Pankaj Vashisth | H7: 1,19,665.56 | I7: Payment Received | J7: Recruiter blank; grouped as Unassigned / Blank Recruiter | L7: Blank recruiter | M7: 9
A8: 178 | B8: 3329 | C8: Delhi | D8: Manorma | E8: Unassigned / Blank Recruiter | F8: MG Motor | G8: Naresh Singh | H8: 43316.91 | I8: Payment Received | J8: Recruiter blank; grouped as Unassigned / Blank Recruiter | L8: Unmapped payment status | M8: 1
A9: 204 | B9: 3274 | C9: Delhi | D9: Manorma | E9: Stuti | F9: JKYMS | G9: Mukesh Thaakur | H9: 46094 | I9: FVHC/26-27/39 | J9: Payment Status needs review | L9: Blank billing amount | M9: 4
A10: 219 | B10: 3269 | C10: Delhi | D10: Manorma | E10: Unassigned / Blank Recruiter | F10: Defsys | G10: Alok Singh | H10: 36985.2 | I10: Payment Received | J10: Recruiter blank; grouped as Unassigned / Blank Recruiter
A11: 241 | B11: 3108 | C11: Delhi | D11: Manorma | E11: Unassigned / Blank Recruiter | F11: Defsys | G11: Parwinder Singh | H11: 50979.6 | I11: Payment Received | J11: Recruiter blank; grouped as Unassigned / Blank Recruiter
A12: 329 | B12: 3439 | C12: Faridabad | D12: Bikash Das | E12: Unassigned / Blank Recruiter | F12: Tylo | G12: Shankara Gouda V Patil | H12: 45500.28 | I12: Payment Received | J12: Recruiter blank; grouped as Unassigned / Blank Recruiter
A13: 514 | B13: 3028 | C13: Gurgaon | D13: Rohit Yadav | E13: Gaurav | F13: VECV Sales | G13: Anurag Mishra | I13: Backout | J13: Billing Amount blank
A14: 525 | B14: 3014 | C14: Faridabad | D14: Bikash Das | E14: Indu | F14: JK Cement | G14: Nikhil Pandya | I14: Payment Received | J14: Billing Amount blank
A15: 528 | B15: 3013 | C15: Faridabad | D15: Bikash Das | E15: Bikash Das | F15: JK Cement | G15: Manish Shukla | I15: Payment Received | J15: Billing Amount blank
